Workbook

Sheet Report
B1: BÁO CÁO RÀ SOÁT TUÂN THỦ — DỰ THẢO SỬA ĐỔI THÔNG TƯ 134/2024/TT-BTC 온라인 증권 거래관련 시행규칙 개정안 준수 점검 보고서
B3: 1. TỔNG QUAN MỨC ĐỘ TUÂN THỦ / 준수 현황 요약
B5: =COUNTA(Checklist!$A$3:$A$66) -> 64 | D5: =COUNTIF(Checklist!$G$3:$G$66,"OK") -> 20 | F5: =COUNTIF(Checklist!$G$3:$G$66,"Cần check lại*") -> 11 | H5: =COUNTIF(Checklist!$G$3:$G$66,"Cần hành động*") -> 33
B6: Hạng mục / 항목 | D6: =D5/$B$5 -> 0.3125 | F6: =F5/$B$5 -> 0.171875 | H6: =H5/$B$5 -> 0.515625
B7: Tổng số hạng mục 총 점검 항목 | D7: Tuân thủ đầy đủ (OK) 완전 준수 | F7: Cần rà soát lại 재확인 필요 | H7: Cần hành động 조치 필요
B10: 2. CHI TIẾT THEO TRẠNG THÁI ĐÁP ỨNG / 충족 상태별 상세
B11: Trạng thái đáp ứng / 충족 상태 | E11: Số lượng 건수 | F11: Tỷ lệ 비율
B12: Đáp ứng (Có) / 충족 (예) | E12: =COUNTIF(Checklist!$F$3:$F$66,"Có*") -> 26 | F12: =E12/$E$16 -> 0.40625
B13: Chưa đáp ứng (Không) / 미충족 (아니오) | E13: =COUNTIF(Checklist!$F$3:$F$66,"Không*") -> 24 | F13: =E13/$E$16 -> 0.375
B14: Chưa đánh giá / 미평가 | E14: =COUNTIF(Checklist!$F$3:$F$66,"Chưa đánh giá*") -> 10 | F14: =E14/$E$16 -> 0.15625
B15: Không áp dụng (N/A) / 해당없음 | E15: =COUNTIF(Checklist!$F$3:$F$66,"N/A*") -> 4 | F15: =E15/$E$16 -> 0.0625
B16: Tổng / 합계 | E16: =SUM(E12:E15) -> 64 | F16: =SUM(F12:F15) -> 1
B18: 3. PHÂN LOẠI XỬ LÝ THEO MỤC / 절별 처리 분류
B19: Mục 절 | C19: Tuân thủ (OK) 완전준수 | D19: Cần rà soát 재확인 | E19: Cần hành động 조치 | F19: Tổng 합계 | G19: % Tuân thủ 준수율 | H19: Nội dung / 내용
B20: 제1절 | C20: =COUNTIFS(Checklist!$B$3:$B$66,"*"&$B20&"*",Checklist!$G$3:$G$66,"OK") -> 6 | D20: =COUNTIFS(Checklist!$B$3:$B$66,"*"&$B20&"*",Checklist!$G$3:$G$66,"Cần check lại*") -> 5 | E20: =COUNTIFS(Checklist!$B$3:$B$66,"*"&$B20&"*",Checklist!$G$3:$G$66,"Cần hành động*") -> 10 | F20: =SUM(C20:E20) -> 21 | G20: =C20/F20 -> 0.28571429 | H20: Yêu cầu chung / 일반 요건 (Điều 5–13)
B21: 제2절 | C21: =COUNTIFS(Checklist!$B$3:$B$66,"*"&$B21&"*",Checklist!$G$3:$G$66,"OK") -> 2 | D21: =COUNTIFS(Checklist!$B$3:$B$66,"*"&$B21&"*",Checklist!$G$3:$G$66,"Cần check lại*") -> 4 | E21: =COUNTIFS(Checklist!$B$3:$B$66,"*"&$B21&"*",Checklist!$G$3:$G$66,"Cần hành động*") -> 10 | F21: =SUM(C21:E21) -> 16 | G21: =C21/F21 -> 0.125 | H21: Kết nối API với bên thứ ba / 제3자 API 연동 (Điều 14–15)
B22: 제3절 | C22: =COUNTIFS(Checklist!$B$3:$B$66,"*"&$B22&"*",Checklist!$G$3:$G$66,"OK") -> 12 | D22: =COUNTIFS(Checklist!$B$3:$B$66,"*"&$B22&"*",Checklist!$G$3:$G$66,"Cần check lại*") -> 2 | E22: =COUNTIFS(Checklist!$B$3:$B$66,"*"&$B22&"*",Checklist!$G$3:$G$66,"Cần hành động*") -> 13 | F22: =SUM(C22:E22) -> 27 | G22: =C22/F22 -> 0.44444444 | H22: An ninh mạng, hạ tầng, lưu trữ & báo cáo / 보안·인프라·보관·보고 (Điều 16–26)
B23: Tổng / 합계 | C23: =SUM(C20:C22) -> 20 | D23: =SUM(D20:D22) -> 11 | E23: =SUM(E20:E22) -> 33 | F23: =SUM(F20:F22) -> 64 | G23: =C23/F23 -> 0.3125
B25: 4. BIỂU ĐỒ TRỰC QUAN / 시각화 차트
B27: Phân loại xử lý / 처리 분류 | C27: Số / 건수
B28: Tuân thủ (OK) / 완전준수 | C28: =D5 -> 20
B29: Cần rà soát / 재확인 | C29: =F5 -> 11
B30: Cần hành động / 조치 | C30: =H5 -> 33
B49: 5. NHẬN ĐỊNH & KHUYẾN NGHỊ / 핵심 인사이트 및 권고
B50: ① Mức độ tuân thủ hiện ở mức thấp: chỉ 20/64 hạng mục (31%) đạt đầy đủ, 33 (52%) cần hành động, 11 (17%) cần rà soát. Theo trạng thái: 26 đáp ứng (41%), 24 chưa đáp ứng (38%). ① 현 준수 수준은 낮음: 64건 중 20건(31%)만 완전 충족, 33건(52%) 조치 필요, 11건(17%) 재확인 필요. 상태 기준 충족 26건(41%), 미충족 24건(38%).
B51: ② Rủi ro tập trung ở Mục 2 (API) và Mục 3 (ANM/hạ tầng): Mục 2 chỉ đạt 12.5% (2/16) – thấp nhất; Mục 3 đạt 44% nhưng có nhiều hạng mục cần hành động nhất (13); Mục 1 đạt 28.6%. ② 위험은 제2절(API)·제3절(보안)에 집중: 제2절 12.5%(2/16) 최저, 제3절 44%이나 조치 항목 최다(13건), 제1절 28.6%.
B52: ③ 9 hạng mục “Chưa đánh giá” (chủ yếu API – Điều 14,15) cần hoàn tất đánh giá sớm để có bức tranh tuân thủ đầy đủ. ③ 미평가 9건(주로 API, 제14·15조)는 담당 지정 및 조기 평가 완료 필요.
B53: ④ Nhóm ưu tiên hành động cao: mã hóa dữ liệu lưu trữ & CSDL (Điều 18,20), kiểm soát truy cập API + rate limit (Điều 15,20–22), xác thực sinh trắc học khi giao dịch/rút tiền (Điều 7,9,12), báo cáo API cho UBCKNN (Điều 14/31). ④ 고우선순위 조치: 데이터·DB 암호화, API 접근통제·rate limit, 생체인증, SSC API 보고.
B54: ⑤ Lưu ý pháp lý: NHSV đang cung cấp API cho đối tác (Stag) nhưng chưa báo cáo UBCKNN – theo TT134 hiện hành có thể bị xem là vi phạm; cần xử lý trước hạn. ⑤ 법적 유의: Stag에 API 제공 중이나 UBCKNN 미보고 – 현행 TT134상 위반 소지, 기한 내 처리 필요.
B55: ⑥ Lộ trình: hoàn thiện hệ thống & dữ liệu KH trong 12 tháng kể từ ngày TT có hiệu lực (Điều 31); danh mục API phải báo cáo trong 3 tháng. Kiến nghị lập kế hoạch hành động theo quý, ưu tiên 33 hạng mục “Cần hành động”. ⑥ 로드맵: 시행 후 12개월 내 시스템·고객데이터 정비(제31조), API 목록은 3개월 내 보고. 33개 조치 항목 우선 분기별 실행계획 수립 권고.

Sheet Cần xử lý_재확인.조치 필요
A1: Các hạng mục CẦN XỬ LÝ — Cần hành động & Cần check lại (mọi tình trạng) · 처리 필요 항목 (조치 / 재확인)
A2: STT 번호 | B2: Mục thuộc về 해당 절 | C2: Hạng mục cần xử lý — Yêu cầu | D2: 처리 대상 항목 | E2: Điều khoản tham chiếu 참조 조항 | F2: Tình trạng 상태 | G2: Phân loại 분류 | H2: Hành động cần thực hiện / Nội dung cần check lại (Rev) | I2: 조치 사항 / 재확인 사항 (한국어) | J2: Người phụ trách (Main) 담당자 | K2: Kế hoạch xử lý 처리 방안 | L2: Thời hạn hoàn thành dự kiến 완료 기한 (예정)
A3: 1 | B3: =_xlfn.LET(_xlpm.n,IFERROR(--MID(E3,6,2),--MID(E3,6,1)),IF(OR(_xlpm.n=14,_xlpm.n=15,_xlpm.n=31),"Mục 2 · 제2절 (API)",IF(AND(_xlpm.n>=5,_xlpm.n<=13),"Mục 1 · 제1절 (Quy định chung)",IF(AND(_xlpm.n>=16,_xlpm.n<=26),"Mục 3 · 제3절 (Hạ tầng)","—")))) -> Mục 1 · 제1절 (Quy định chung) | C3: Công bố thông tin về các dịch vụ cung cấp, bảo đảm khách hàng tiếp cận được trước hoặc ngay tại thời điểm đăng ký sử dụng dịch vụ (khoản 1, 2 Điều 5). | D3: 제공 서비스에 관한 정보를 공시하여 고객이 가입 전 또는 가입 시점에 접근 가능하도록 보장(제5조 제1·2항). | E3: ĐIỀU 5 — 제5조 | F3: Có / 예 | G3: Cần hành động / 조치 필요 | H3: Bổ sung công bố thông tin dịch vụ trên web/app để KH tiếp cận trước/khi đăng ký (Theo khoản 2 Điều 5) • (b) Bổ sung 'hình thức xác thực giao dịch' vào mục hạn mức giao dịch (nếu có). • (d) Cập nhật bản công bố rủi ro chi tiết hơn. Mục (a) cách thức cung cấp & (c) trang thiết bị/điều kiện sử dụng đã có thông tin trên web - Cách thức cung cấp: https://nhsv.vn/page/cong-cu-giao-dich.html - Trang thiết bị điều kiện sử dụng: https://nhsv.vn/page/huong-dan-giao-dich-tren-mobile-nhsv-pro.html | I3: 고객이 가입 전/가입 시점에 접근할 수 있도록 웹/앱에 서비스 정보 공시 보완(제5조 제2항). • (b) 거래 한도 항목에 '거래 인증 방식' 추가(있는 경우). • (d) 위험 공시 자료를 더 상세히 갱신. (a) 제공 방식 및 (c) 장비/이용 조건은 이미 웹에 게시됨 - 제공 방식: https://nhsv.vn/page/cong-cu-giao-dich.html - 장비/이용 조건: https://nhsv.vn/page/huong-dan-giao-dich-tren-mobile-nhsv-pro.html | J3: Ms Ngân
A4: 2 | B4: =_xlfn.LET(_xlpm.n,IFERROR(--MID(E4,6,2),--MID(E4,6,1)),IF(OR(_xlpm.n=14,_xlpm.n=15,_xlpm.n=31),"Mục 2 · 제2절 (API)",IF(AND(_xlpm.n>=5,_xlpm.n<=13),"Mục 1 · 제1절 (Quy định chung)",IF(AND(_xlpm.n>=16,_xlpm.n<=26),"Mục 3 · 제3절 (Hạ tầng)","—")))) -> Mục 1 · 제1절 (Quy định chung) | C4: Công ty chứng khoán phải được UBCKNN chấp thuận trước khi cung cấp dịch vụ GDCK trực tuyến; hồ sơ theo Điều 203 NĐ 155/2020/NĐ-CP; tài liệu theo Phụ lục I (khoản 3 Điều 5). | D4: 증권회사는 온라인 증권거래 서비스 제공 전 UBCKNN 승인을 취득; 서류는 NĐ 155/2020 제203조, 양식은 부록 I (제5조 제3항). | E4: ĐIỀU 5 — 제5조 | F4: Có / 예 | G4: Cần check lại / 재확인 필요 | H4: Check lại với UBCKNN: giấy phép hiện tại là QĐ 454/QĐ-UBCK (2017, cấp cho Woori CBV, trước TT134/2017). Xác định có phải nộp lại hồ sơ đăng ký cung cấp dịch vụ GDTT (theo Điều 203 NĐ155/2020 + Phụ lục I) hay không. * Phụ lục I: BÁO CÁO THIẾT KẾ HỆ THỐNG GIAO DỊCH TRỰC TUYẾN gồm: tài liệu về nhân sự vận hành hệ thống, hệ thống giao dịch, giải pháp kỹ thuật bảo đảm an toàn hệ thống, hệ thống lưu trữ dữ liệu dự phòng và khắc phục sự cố. | I4: UBCKNN에 재확인: 현재 라이선스는 QĐ 454/QĐ-UBCK(2017년, Woori CBV에 발급, TT134/2017 이전). 온라인거래 서비스 제공 등록 서류(NĐ155/2020 제203조 + 부록 I)를 다시 제출해야 하는지 확인. * 부록 I: 온라인거래시스템 설계 보고서 — 시스템 운영 인력, 거래 시스템, 시스템 안전 보장 기술 솔루션, 예비 데이터 저장 및 사고 복구 시스템 관련 자료 포함. | J4: Ms Nhung | K4: Liên hệ với Quản lý Thành viên và Vụ Pháp chế - Đối ngoại SSC để hỏi thông tin | L4: 26/6/2026
A5: 3 | B5: =_xlfn.LET(_xlpm.n,IFERROR(--MID(E5,6,2),--MID(E5,6,1)),IF(OR(_xlpm.n=14,_xlpm.n=15,_xlpm.n=31),"Mục 2 · 제2절 (API)",IF(AND(_xlpm.n>=5,_xlpm.n<=13),"Mục 1 · 제1절 (Quy định chung)",IF(AND(_xlpm.n>=16,_xlpm.n<=26),"Mục 3 · 제3절 (Hạ tầng)","—")))) -> Mục 1 · 제1절 (Quy định chung) | C5: Cung cấp dịch vụ phải thể hiện bằng hợp đồng hoặc điều khoản của hợp đồng với khách hàng (khoản 4 Điều 5). Bao gồm các thông tin sau trong HĐ: Phương thức giao dịch trực tuyến & loại giao dịch tương ứng SĐT di dộng đăng ký sử dụng dịch vụ. Tổ chức cung cấp dịch vụ có biện pháp xác minh để đảm bảo số điện thoại này thuộc quyền sử dụng hợp pháp của KH Các rủi ro & trách nhiệm bồi thường của mỗi bên | D5: 서비스 제공은 고객과의 계약 또는 계약 조항으로 표시되어야 함(제5조 제4항). 계약에 다음 정보 포함: • 온라인 거래 방식 및 해당 거래 유형 • 서비스 가입에 등록한 휴대전화 번호. 서비스 제공기관은 해당 번호가 고객의 적법한 사용 권한에 속함을 확인하는 조치 보유 • 각 당사자의 위험 및 배상 책임 | E5: ĐIỀU 5 — 제5조 | F5: Có / 예 | G5: Cần hành động / 조치 필요 | H5: NHSV cần có biện pháp xác minh SĐT di động thuộc quyền sử dụng hợp pháp của KH (hiện CHƯA có) | I5: NHSV는 휴대전화 번호가 고객의 적법한 사용 권한에 속하는지 확인하는 조치를 마련해야 함(현재 없음). | J5: Mr Đức
A6: 4 | B6: =_xlfn.LET(_xlpm.n,IFERROR(--MID(E6,6,2),--MID(E6,6,1)),IF(OR(_xlpm.n=14,_xlpm.n=15,_xlpm.n=31),"Mục 2 · 제2절 (API)",IF(AND(_xlpm.n>=5,_xlpm.n<=13),"Mục 1 · 제1절 (Quy định chung)",IF(AND(_xlpm.n>=16,_xlpm.n<=26),"Mục 3 · 제3절 (Hạ tầng)","—")))) -> Mục 1 · 제1절 (Quy định chung) | C6: Ban hành quy trình giao dịch trực tuyến phù hợp với Thông tư, pháp luật về chứng khoán và pháp luật có liên quan (khoản 5 Điều 5). | D6: 본 시행규칙, 증권법 및 관련 법규에 부합하는 온라인 거래 절차 제정(제5조 제5항). | E6: ĐIỀU 5 — 제5조 | F6: Có / 예 | G6: Cần hành động / 조치 필요 | H6: NHSV đã có QT mở tài khoản eKYC; QT QLL GDTT; QT đăng ký, hủy sử dụng DV GDCKTT; QT KSRR trong HĐ GDTT; QT khắc phục sự cố hệ thống GDTT; QT vận hành hệ thống GDTT HNX/HSX Bổ sung nội dung xác thực vào các quy trình đã có hoặc ban hành quy trình mới: • QT rút tiền: thêm xác thực theo giá trị giao dịch. • QT mở/đóng tài khoản eKYC: thêm xác thực sinh trắc học. • QT quản lý lệnh: thêm xác thực lệnh. • Cân nhắc ban hành QT tổng quát về xác thực giao dịch/thiết bị. | I6: NHSV는 eKYC 계좌개설 절차; 온라인거래 관리 절차; 온라인 증권거래 서비스 가입·해지 절차; 온라인거래 위험통제 절차; 온라인거래시스템 사고복구 절차; HNX/HSX 온라인거래시스템 운영 절차를 이미 보유. 기존 절차에 인증 내용을 보완하거나 신규 절차 제정: • 출금 절차: 거래 금액별 인증 추가. • eKYC 계좌 개설/해지 절차: 생체인증 추가. • 주문 관리 절차: 주문 인증 추가. • 거래/기기 인증에 관한 일반 절차 제정 검토. | J6: Ms Ngân
A7: 5 | B7: =_xlfn.LET(_xlpm.n,IFERROR(--MID(E7,6,2),--MID(E7,6,1)),IF(OR(_xlpm.n=14,_xlpm.n=15,_xlpm.n=31),"Mục 2 · 제2절 (API)",IF(AND(_xlpm.n>=5,_xlpm.n<=13),"Mục 1 · 제1절 (Quy định chung)",IF(AND(_xlpm.n>=16,_xlpm.n<=26),"Mục 3 · 제3절 (Hạ tầng)","—")))) -> Mục 1 · 제1절 (Quy định chung) | C7: Khi cung cấp dịch vụ, công ty chứng khoán phải trực tiếp thực hiện: a) Xác thực giao dịch mở tài khoản chứng khoán; b) Xác thực giao dịch đặt lệnh mua bán chứng khoán (điểm a, b khoản 8 Điều 5). | D7: 서비스 제공 시 증권회사가 직접 수행: a) 증권계좌 개설 거래 인증; b) 증권 매매주문 거래 인증(제5조 제8항 a·b호). | E7: ĐIỀU 5 — 제5조 (tiếp) | F7: Không / 아니오 | G7: Cần hành động / 조치 필요 | H7: Đảm bảo xác thực bắt buộc tối thiểu 1 lần cho giao dịch đầu tiên mỗi phiên đăng nhập. Mở TKCK đã có OCR CCCD + khuôn mặt; rà soát lại bước xác thực khi đặt lệnh. | I7: 로그인 세션별 최초 거래에 대해 최소 1회 인증을 의무화. 증권계좌 개설은 이미 CCCD OCR + 얼굴 인증 적용; 주문 시 인증 단계 재점검. | J7: Mr Đức
A8: 6 | B8: =_xlfn.LET(_xlpm.n,IFERROR(--MID(E8,6,2),--MID(E8,6,1)),IF(OR(_xlpm.n=14,_xlpm.n=15,_xlpm.n=31),"Mục 2 · 제2절 (API)",IF(AND(_xlpm.n>=5,_xlpm.n<=13),"Mục 1 · 제1절 (Quy định chung)",IF(AND(_xlpm.n>=16,_xlpm.n<=26),"Mục 3 · 제3절 (Hạ tầng)","—")))) -> Mục 1 · 제1절 (Quy định chung) | C8: Rà soát, lập kế hoạch, hoàn thiện hệ thống & dữ liệu của khách hàng bảo đảm tuân thủ quy định trong thời hạn 01 năm kể từ ngày Thông tư có hiệu lực thi hành (Điều 31). | D8: 규정 준수를 위해 시스템 및 고객 데이터를 점검·계획·정비; 시행일로부터 1년 이내 완료(제31조). | E8: ĐIỀU 5 — 제5조 (tiếp) | F8: Chưa đánh giá / 미평가 | G8: Cần hành động / 조치 필요 | H8: Điều khoản chuyển tiếp (Điều 31): thực hiện sau khi Thông tư có hiệu lực — rà soát, hoàn thiện hệ thống & dữ liệu KH trong vòng 1 năm. | I8: 경과 규정(제31조): 시행규칙 발효 후 시행 — 1년 이내에 시스템 및 고객 데이터 점검·정비. | J8: Ms Nhung, Mr Văn, Mr Đức
A9: 7 | B9: =_xlfn.LET(_xlpm.n,IFERROR(--MID(E9,6,2),--MID(E9,6,1)),IF(OR(_xlpm.n=14,_xlpm.n=15,_xlpm.n=31),"Mục 2 · 제2절 (API)",IF(AND(_xlpm.n>=5,_xlpm.n<=13),"Mục 1 · 제1절 (Quy định chung)",IF(AND(_xlpm.n>=16,_xlpm.n<=26),"Mục 3 · 제3절 (Hạ tầng)","—")))) -> Mục 1 · 제1절 (Quy định chung) | C9: OTP đáp ứng thời hạn hiệu lực: . Thẻ ma trận có thời hạn dùng tối đa 01 năm. SMS 05 phút, Voice 03 phút, Email 05 phút, Thẻ ma trận 02 phút, Soft OTP 02 phút, Token OTP 02 phút (Điều 8). | D9: OTP 유효시간 준수: OTP카드 1년, SMS 5분, Voice 3분, Email 5분, 매트릭스 카드 2분, Soft OTP 2분, Token OTP 2분(제8조). | E9: ĐIỀU 7–9 — 제7~9조 | F9: Không / 아니오 | G9: Cần hành động / 조치 필요 | H9: Rà soát lại và điều chỉnh một số nội dung gửi, thời gian hiệu lực của OTP 1. SMS OTP: Rà soát lại toàn bộ các SMS OTP về thông tin gửi (hiện tại gửi đang không gửi kèm mục đích sử dụng), Rà soát lại thời gian hiệu lực của SMS OTP 2. Voice OTP: NHSV Không sử dụng, không cần rà soát 3. Mail OTP: NHSV Không sử dụng, không cần rà soát 4. Thẻ OTP: Thẻ ma trận OTP của NHSV hiện không đáp ứng về thời hạn sử dụng. Phải sửa đổi thời gian về tối đa 1 năm từ ngày đăng kí thẻ. Nghiên cứu triển khai cùng CS 5. Soft OTP : Soft OTP của NHSV hiện đã đáp ứng về thời gian hiệu lực không quá 2P. Cần rà soát Khi KH kích hoạt Smart OTP lần đầu, theo quy định phải phải yêu cầu khớp đúg SMS OTP qua số điện thoại đã đăng kí và khớp đúng thông tin sinh trắng học của KH theo ảnh khuôn mặt/vân tay/mống mắt/ADN/giọng nói. NHSV đã yêu cầu KH phải kích hoạt Smart OTP trước khi sử dụng nhưng mã kích hoạt chỉ được sử dụng trên 1 thiết bị và hiệu lực sử dụng cần rà soát lại Phần mềm Soft OTP phải có chức năng kiểm soát truy cập. Rà soát trường hợp truy cập sai liên tiếp quá số lần do tổ chức cung cấp dịch vụ quy định (nhưng không quá 10 lần), phần mềm Soft OTP phải tự động khóa không cho khách hàng sử dụng tiếp. Tổ chức cung cấp dịch vụ chỉ mở khóa phần mềm Soft OTP khi khách hàng yêu cầu và phải kiểm tra, nhận biết khách hàng trước khi thực hiện mở khóa, bảo đảm chống gian lận, giả mạo; 6. Token OTP: NHSV hiện không sử dụng | I9: OTP의 발송 내용 및 유효시간 일부를 점검·조정: 1. SMS OTP: 모든 SMS OTP의 발송 정보 재점검(현재 사용 목적을 함께 발송하지 않음), SMS OTP 유효시간 재점검. 2. Voice OTP: NHSV 미사용, 점검 불필요. 3. Mail OTP: NHSV 미사용, 점검 불필요. 4. OTP 카드: NHSV 매트릭스 OTP 카드는 현재 사용 기한 요건 미충족. 카드 등록일로부터 최대 1년으로 기간 수정 필요. CS와 함께 시행 연구. 5. Soft OTP: NHSV Soft OTP는 현재 2분 이내 유효시간 요건 충족. 고객이 Smart OTP를 최초 활성화할 때 규정상 등록 전화번호로 SMS OTP 일치 및 얼굴/지문/홍채/DNA/음성 생체정보 일치를 요구해야 함 — 점검 필요. NHSV는 사용 전 Smart OTP 활성화를 요구하나 활성화 코드는 1개 기기에서만 사용되며 유효기간은 재점검 필요. Soft OTP 소프트웨어는 접근통제 기능을 보유해야 함. 서비스 제공기관이 정한 횟수(단, 10회 이하)를 초과하여 연속 오접속 시 Soft OTP가 자동 잠금되어 고객이 계속 사용하지 못하도록 점검. 잠금 해제는 고객 요청 시에만 하며, 해제 전 고객을 확인·식별하여 부정·위조를 방지. 6. Token OTP: NHSV 현재 미사용. | J9: Mr Đức
A10: 8 | B10: =_xlfn.LET(_xlpm.n,IFERROR(--MID(E10,6,2),--MID(E10,6,1)),IF(OR(_xlpm.n=14,_xlpm.n=15,_xlpm.n=31),"Mục 2 · 제2절 (API)",IF(AND(_xlpm.n>=5,_xlpm.n<=13),"Mục 1 · 제1절 (Quy định chung)",IF(AND(_xlpm.n>=16,_xlpm.n<=26),"Mục 3 · 제3절 (Hạ tầng)","—")))) -> Mục 1 · 제1절 (Quy định chung) | C10: Các điều khoản về khớp đúng thông tin sung trắc học. Sinh trắc học khuôn mặt đạt chuẩn FIDO Biometric Requirement: FRR < 5%, FAR < 0,01% (tập mẫu ≥ 10.000); có phát hiện tấn công giả mạo vật thể sống (PAD) (khoản 1 Điều 9). | D10: 얼굴 생체인증 FIDO Biometric Requirement 충족: FRR<5%, FAR<0.01%(표본 1만 이상); 생체 위조공격탐지(PAD) 보유(제9조 제1항). | E10: ĐIỀU 7–9 — 제7~9조 | F10: Chưa đánh giá / 미평가 | G10: Cần check lại / 재확인 필요 | H10: IT check lại: hình thức sinh trắc học qua eKYC của NHSV đã đáp ứng chuẩn (PAD, FRR<5%, FAR<0,01%) chưa; chuẩn bị áp dụng sinh trắc học khi KH rút tiền trên 10tr VND | I10: IT 재점검: NHSV의 eKYC 생체인증 방식이 기준(PAD, FRR<5%, FAR<0.01%)을 충족하는지; 고객이 1천만 VND 초과 출금 시 생체인증 적용 준비. | J10: Mr Đức
A11: 9 | B11: =_xlfn.LET(_xlpm.n,IFERROR(--MID(E11,6,2),--MID(E11,6,1)),IF(OR(_xlpm.n=14,_xlpm.n=15,_xlpm.n=31),"Mục 2 · 제2절 (API)",IF(AND(_xlpm.n>=5,_xlpm.n<=13),"Mục 1 · 제1절 (Quy định chung)",IF(AND(_xlpm.n>=16,_xlpm.n<=26),"Mục 3 · 제3절 (Hạ tầng)","—")))) -> Mục 1 · 제1절 (Quy định chung) | C11: Giải pháp PAD do tổ chức tự triển khai hoặc dùng của bên thứ ba phải được chứng nhận bởi Liên minh FIDO hoặc tổ chức quốc tế có tiêu chuẩn tương đương/cao hơn (Điều 9). | D11: PAD 솔루션은 자체 구축 또는 제3자 사용 시 FIDO Alliance 또는 동등·상위 기준 국제기관의 인증 필요(제9조). | E11: ĐIỀU 7–9 — 제7~9조 | F11: Chưa đánh giá / 미평가 | G11: Cần check lại / 재확인 필요 | H11: Check lại xem đối tác cung cấp giải pháp đã đáp ứng chứng nhận bởi Liên minh FIDO hoặc tổ chức Quốc tế có tiêu chuẩn tương tự hay chưa | I11: 솔루션 공급 파트너가 FIDO Alliance 또는 동등 기준 국제기관의 인증을 충족했는지 재확인. | J11: Mr Đức
A12: 10 | B12: =_xlfn.LET(_xlpm.n,IFERROR(--MID(E12,6,2),--MID(E12,6,1)),IF(OR(_xlpm.n=14,_xlpm.n=15,_xlpm.n=31),"Mục 2 · 제2절 (API)",IF(AND(_xlpm.n>=5,_xlpm.n<=13),"Mục 1 · 제1절 (Quy định chung)",IF(AND(_xlpm.n>=16,_xlpm.n<=26),"Mục 3 · 제3절 (Hạ tầng)","—")))) -> Mục 1 · 제1절 (Quy định chung) | C12: Các quy định bổ sung về khớp đúng thông tin sinh trắng học Khóa chức năng khi sai quá số lần quy định (≤10 lần), chỉ mở khi KH yêu cầu & nhận biết KH. Thời gian khớp đúng thông tin sinh trắc học kể từ thời điểm hệ thống ghi nhận yêu cầu xác thực của KH là tối đa 03 phút. Đối chiếu khớp đúng thông tin STH của KH với 1 trong các dữ liệu: a) Dữ liệu sinh trắc học được lưu trong bộ phận lưu trữ thông tin được mã hóa của thẻ CCCD hoặc thẻ CC đã được xác thực chính xác là do cơ quan Công an cấp hoặc thông qua xác thực tài khoản định danh điện tử của người đó do Hệ thống định danh và xác thực điện tử tạo lập; b) Dữ liệu sinh trắc học đã được thu thập và kiểm tra; bảo đảm sự khớp đúng giữa dữ liệu sinh trắc học của người đó với dữ liệu sinh trắc học trong bộ phận lưu trữ thông tin được mã hóa của thẻ CCCD hoặc thẻ CC đã được xác thực chính xác là do cơ quan Công an cấp, hoặc với dữ liệu sinh trắc học của người đó thông qua xác thực tài khoản định danh điện tử do Hệ thống định danh và xác thực điện tử tạo lập; c) Dữ liệu sinh trắc học của người đó được lưu trong Cơ sở dữ liệu quốc gia về dân cư trong trường hợp sử dụng thẻ CCCD không có bộ phận lưu trữ thông tin được mã hóa. | D12: 생체정보 일치에 관한 추가 규정. 규정 횟수(10회 이하) 초과 오류 시 기능 잠금, 고객 요청 및 고객 확인 시에만 해제. 생체정보 일치 확인 시간은 시스템이 고객의 인증 요청을 기록한 시점부터 최대 3분. 고객의 생체정보를 다음 데이터 중 하나와 대조하여 일치 확인: a) 공안기관 발급으로 정확히 인증된 CCCD(시민카드) 또는 CC 카드의 암호화 정보저장부에 저장된 생체정보, 또는 전자식별인증시스템이 생성한 본인의 전자식별계정 인증을 통한 생체정보; b) 수집·검사된 생체정보로서, 본인의 생체정보가 공안기관 발급으로 인증된 CCCD 또는 CC 카드의 암호화 저장부 생체정보와 일치하거나, 전자식별인증시스템이 생성한 본인의 전자식별계정 인증 생체정보와 일치함을 보장; c) 암호화 정보저장부가 없는 CCCD 카드 사용 시, 국가 인구 데이터베이스에 저장된 본인의 생체정보. | E12: ĐIỀU 7–9 — 제7~9조 | F12: Chưa đánh giá / 미평가 | G12: Cần check lại / 재확인 필요 | H12: Rà soát lại đáp ứng của hệ thống, giải pháp sắp triển khai xem đã đáp ứng: • Khóa chức năng khi sai >10 lần, chỉ mở khi KH yêu cầu + nhận biết KH. • Thời gian khớp sinh trắc học tối đa 3 phút. • Đối chiếu STH với dữ liệu: chip CCCD / tài khoản định danh điện tử / CSDL quốc gia về dân cư. | I12: 도입 예정 시스템·솔루션이 다음을 충족하는지 재점검: • 10회 초과 오류 시 기능 잠금, 고객 요청 + 고객 확인 시에만 해제. • 생체정보 일치 시간 최대 3분. • 생체정보를 CCCD 칩 / 전자식별계정 / 국가 인구 데이터베이스와 대조. | J12: Mr Đức
A13: 11 | B13: =_xlfn.LET(_xlpm.n,IFERROR(--MID(E13,6,2),--MID(E13,6,1)),IF(OR(_xlpm.n=14,_xlpm.n=15,_xlpm.n=31),"Mục 2 · 제2절 (API)",IF(AND(_xlpm.n>=5,_xlpm.n<=13),"Mục 1 · 제1절 (Quy định chung)",IF(AND(_xlpm.n>=16,_xlpm.n<=26),"Mục 3 · 제3절 (Hạ tầng)","—")))) -> Mục 1 · 제1절 (Quy định chung) | C13: Mở/đóng tài khoản GDCK & tài khoản lưu ký chứng khoán: xác thực khớp đúng sinh trắc học (Điều 9) với cá nhân & người đại diện hợp pháp của tổ chức; hợp đồng xác nhận bằng chữ ký số (khoản 1 Điều 12). | D13: 증권계좌·예탁계좌 개설/해지: 개인 및 법인 대표자에 대해 생체정보 일치 인증(제9조); 계약은 전자서명으로 확인(제12조 제1항). | E13: ĐIỀU 12–13 — 제12~13조 | F13: Không / 아니오 | G13: Cần hành động / 조치 필요 | H13: Đóng tài khoản hiện qua quầy hoặc gọi điện xác nhận — CHƯA xác thực sinh trắc học. Cần: • Cân nhắc mở tính năng đóng TK online. Bổ sung xác thực sinh trắc học khi đóng TK. • KH tổ chức nếu cho mở eKYC cũng cần sinh trắc học khuôn mặt. | I13: 현재 계좌 해지는 영업점 또는 전화 확인으로 진행 — 생체인증 미적용. 필요사항: • 온라인 계좌 해지 기능 도입 검토. 계좌 해지 시 생체인증 추가. • 법인 고객도 eKYC 개설을 허용하는 경우 얼굴 생체인증 필요. | J13: Ms Ngân
A14: 12 | B14: =_xlfn.LET(_xlpm.n,IFERROR(--MID(E14,6,2),--MID(E14,6,1)),IF(OR(_xlpm.n=14,_xlpm.n=15,_xlpm.n=31),"Mục 2 · 제2절 (API)",IF(AND(_xlpm.n>=5,_xlpm.n<=13),"Mục 1 · 제1절 (Quy định chung)",IF(AND(_xlpm.n>=16,_xlpm.n<=26),"Mục 3 · 제3절 (Hạ tầng)","—")))) -> Mục 1 · 제1절 (Quy định chung) | C14: Giao dịch chứng khoán trực tuyến: áp dụng xác thực khớp đúng sinh trắc học (Điều 9); xác thực ít nhất với giao dịch đầu tiên mỗi phiên đăng nhập; xác thực & giao dịch trên cùng một thiết bị (khoản 2 Điều 12). | D14: 온라인 증권거래: 생체정보 일치 인증(제9조) 적용; 로그인 세션별 최초 거래 인증; 인증과 거래는 동일 기기에서 수행(제12조 제2항). | E14: ĐIỀU 12–13 — 제12~13조 | F14: Không / 아니오 | G14: Cần hành động / 조치 필요 | H14: Triển khai áp dụng xác thực sinh trắc học (Điều 9) cho GDCK trực tuyến — ít nhất với giao dịch đầu tiên mỗi phiên đăng nhập; xác thực & giao dịch trên cùng một thiết bị. | I14: 온라인 증권거래에 생체인증(제9조) 적용 시행 — 최소한 로그인 세션별 최초 거래에 대해; 인증과 거래는 동일 기기에서 수행. | J14: Mr Đức
A15: 13 | B15: =_xlfn.LET(_xlpm.n,IFERROR(--MID(E15,6,2),--MID(E15,6,1)),IF(OR(_xlpm.n=14,_xlpm.n=15,_xlpm.n=31),"Mục 2 · 제2절 (API)",IF(AND(_xlpm.n>=5,_xlpm.n<=13),"Mục 1 · 제1절 (Quy định chung)",IF(AND(_xlpm.n>=16,_xlpm.n<=26),"Mục 3 · 제3절 (Hạ tầng)","—")))) -> Mục 1 · 제1절 (Quy định chung) | C15: Đặt lệnh qua điện thoại: KH dùng số điện thoại đã đăng ký + tối thiểu số định danh cá nhân & thông tin xác thực yếu tố bí mật; chỉ thực hiện khi thông tin trùng khớp dữ liệu đã lưu (khoản 3 Điều 12). | D15: 전화 주문: 등록된 전화번호 + 최소 개인식별번호 및 비밀요소 인증정보 사용; 등록·보관된 정보와 일치할 때만 거래 수행(제12조 제3항). | E15: ĐIỀU 12–13 — 제12~13조 | F15: Có / 예 | G15: Cần hành động / 조치 필요 | H15: Hiện đáp ứng (chỉ giao dịch khi thông tin KH trùng khớp dữ liệu đã đăng ký/lưu). Theo dõi yêu cầu CS đã gửi BA: đồng bộ SĐT đăng ký của KH + hiển thị thông tin KH khi KH gọi đến NHSV từ đúng SĐT đã đăng ký. | I15: 현재 충족(고객 정보가 등록·보관 데이터와 일치할 때만 거래). CS가 BA에 보낸 요청 추적: 고객 등록 전화번호 동기화 + 고객이 등록된 전화번호로 NHSV에 전화 시 고객 정보 표시. | J15: Ms Ngân
A16: 14 | B16: =_xlfn.LET(_xlpm.n,IFERROR(--MID(E16,6,2),--MID(E16,6,1)),IF(OR(_xlpm.n=14,_xlpm.n=15,_xlpm.n=31),"Mục 2 · 제2절 (API)",IF(AND(_xlpm.n>=5,_xlpm.n<=13),"Mục 1 · 제1절 (Quy định chung)",IF(AND(_xlpm.n>=16,_xlpm.n<=26),"Mục 3 · 제3절 (Hạ tầng)","—")))) -> Mục 1 · 제1절 (Quy định chung) | C16: Rút/chuyển tiền khỏi tài khoản GDCK: < 10 triệu VND áp dụng tối thiểu 1 hình thức tại Điều 7; ≥ 10 triệu VND áp dụng tối thiểu hình thức Xác thực khớp đúng thông tin sinh trắc học. | D16: 증권계좌 출금·이체: 1천만 VND 미만 제7조 1가지 이상; 1천만 VND 이상 제9조 (생체인식) 인증 적용(제12조 제4항). | E16: ĐIỀU 12–13 — 제12~13조 | F16: Không / 아니오 | G16: Cần hành động / 조치 필요 | H16: Bổ sung xác thực rút tiền theo giá trị: • Dưới 10 triệu: CHƯA yêu cầu OTP → áp dụng tối thiểu 1 hình thức tại Điều 7. • Từ 10 triệu trở lên: CHƯA có sinh trắc học → áp dụng xác thực sinh trắc học. | I16: 금액별 출금 인증 보완: • 1천만 VND 미만: 현재 OTP 미요구 → 제7조의 1가지 이상 방식 적용. • 1천만 VND 이상: 현재 생체인증 없음 → 생체인증 적용. | J16: Mr Đức
... A47: 45 | B47: =_xlfn.LET(_xlpm.n,IFERROR(--MID(E47,6,2),--MID(E47,6,1)),IF(OR(_xlpm.n=14,_xlpm.n=15,_xlpm.n=31),"Mục 2 · 제2절 (API)",IF(AND(_xlpm.n>=5,_xlpm.n<=13),"Mục 1 · 제1절 (Quy định chung)",IF(AND(_xlpm.n>=16,_xlpm.n<=26),"Mục 3 · 제3절 (Hạ tầng)","—")))) -> Mục 3 · 제3절 (Hạ tầng) | C47: Công khai danh mục các dịch vụ API đang triển khai (nếu có) để cung cấp dịch vụ trực tuyến trên trang thông tin điện tử (khoản 2 Điều 26). | D47: 온라인 서비스 제공을 위해 도입 중인 API 서비스 목록(있는 경우)을 웹사이트에 공개(제26조 제2항). | E47: ĐIỀU 26 — 제26조 | F47: Không / 아니오 | G47: Cần hành động / 조치 필요 | H47: Khi Thông tư ban hành & có hiệu lực: tổng hợp danh mục dịch vụ API đang triển khai (tên dịch vụ, phạm vi dữ liệu, hình thức xác thực-bảo mật, danh sách bên thứ ba) báo cáo Ủy ban & công bố trên website. | I47: 시행규칙 공포·발효 시: 도입 중인 API 서비스 목록(서비스명, 데이터 범위, 인증·보안 방식, 제3자 목록)을 종합하여 UBCKNN에 보고하고 웹사이트에 공개. | J47: Mr Hoàng

Sheet Checklist
A1: Checklist tuân thủ — Chương II · 제2장 준수 점검표 (Đánh giá tình trạng tuân thủ của NHSV)
A2: STT | B2: Mục | C2: Điều khoản | D2: Yêu cầu (Tiếng Việt) | E2: 요건 (한국어) | F2: Tình trạng 상태 | G2: Check (Nhung) | H2: Ghi chú / Đánh giá 비고 / 평가 | I2: Phụ trách 담당 | J2: Note
A3: 1 | B3: MỤC 1 · 제1절_Yêu cầu chung | C3: ĐIỀU 5 — 제5조 | D3: Công bố thông tin về các dịch vụ cung cấp, bảo đảm khách hàng tiếp cận được trước hoặc ngay tại thời điểm đăng ký sử dụng dịch vụ (khoản 1, 2 Điều 5). | E3: 제공 서비스에 관한 정보를 공시하여 고객이 가입 전 또는 가입 시점에 접근 가능하도록 보장(제5조 제1·2항). | F3: Có / 예 | G3: Cần hành động | H3: Nội dung công bố (khoản 2): a) Cách thức cung cấp & truy cập dịch vụ theo từng phương tiện truy cập: https://nhsv.vn/page/cong-cu-giao-dich.html b) Hạn mức giao dịch (nếu có) & hình thức xác thực GD => cần bổ sung hình thức xác thực GD c) Trang thiết bị cần thiết & điều kiện sử dụng: https://nhsv.vn/page/huong-dan-giao-dich-tren-mobile-nhsv-pro.html d) Các rủi ro theo khoản 1 Điều 26: https://nhsv.vn/uploadfile/source/Thuvientailieu/Cong_bo_rui_ro_GD_truc_tuyen.pdf (đã có nhưng cần chi tiết hơn) e) Thông tin khác cần thiết. | I3: Comp, Legal, Mr Duc | J3: Legal và Pháp chế lead - Phối hợp với IT
A4: 2 | B4: MỤC 1 · 제1절_Yêu cầu chung | C4: ĐIỀU 5 — 제5조 | D4: Công ty chứng khoán phải được UBCKNN chấp thuận trước khi cung cấp dịch vụ GDCK trực tuyến; hồ sơ theo Điều 203 NĐ 155/2020/NĐ-CP; tài liệu theo Phụ lục I (khoản 3 Điều 5). | E4: 증권회사는 온라인 증권거래 서비스 제공 전 UBCKNN 승인을 취득; 서류는 NĐ 155/2020 제203조, 양식은 부록 I (제5조 제3항). | F4: Có / 예 | G4: Cần check lại | H4: Phụ lục I TT – BÁO CÁO THIẾT KẾ HỆ THỐNG GIAO DỊCH TRỰC TUYẾN gồm: tài liệu về nhân sự vận hành hệ thống, hệ thống giao dịch, giải pháp kỹ thuật bảo đảm an toàn hệ thống, hệ thống lưu trữ dữ liệu dự phòng và khắc phục sự cố. Ngày 10/5/2017, UBCKNN ban hành Quyết định số 454/QĐ-UBCK về việc chấp thuận đăng ký cung cấp dịch vụ giao dịch chứng khoán trực tuyến của CTCP Chứng khoán Woori CBV https://ssc.gov.vn/webcenter/portal/ubck/pages_r/l/chitit?dDocName=APPSSCGOVVN162112128 (trước hiệu lực của TT134/2017) -> Check lại xem có phải làm lại hồ sơ đki cấp dịch vụ GDTT hay ko | I4: Comp, Legal, Mr Duc
A5: 3 | B5: MỤC 1 · 제1절_Yêu cầu chung | C5: ĐIỀU 5 — 제5조 | D5: Cung cấp dịch vụ phải thể hiện bằng hợp đồng hoặc điều khoản của hợp đồng với khách hàng (khoản 4 Điều 5). | E5: 서비스 제공은 고객과의 계약 또는 계약 조항으로 표시되어야 함(제5조 제4항). | F5: Có / 예 | G5: Cần hành động | H5: Phương thức giao dịch trực tuyến & loại giao dịch tương ứng => Đã có SĐT di dộng đăng ký sử dụng dịch vụ => Đã có + biện pháp xác minh SĐT thuộc quyền sử dụng hợp pháp của KH => Chưa có Các rủi ro & trách nhiệm bồi thường của mỗi bên => Đã có | I5: Comp, Legal, Mr Duc | J5: Có thể kết nối với nhà mạng để xử lý -> Mr Đức trao đổi với nhà mạng
A6: 4 | B6: MỤC 1 · 제1절_Yêu cầu chung | C6: ĐIỀU 5 — 제5조 | D6: Ban hành quy trình giao dịch trực tuyến phù hợp với Thông tư, pháp luật về chứng khoán và pháp luật có liên quan (khoản 5 Điều 5). | E6: 본 시행규칙, 증권법 및 관련 법규에 부합하는 온라인 거래 절차 제정(제5조 제5항). | F6: Có / 예 | G6: Cần hành động | H6: Đã có các Quy trình sau: QT mở tài khoản eKYC; QT QLL GDTT; QT đăng ký, hủy sử dụng DV GDCKTT; QT KSRR trong HĐ GDTT; QT khắc phục sự cố hệ thống GDTT; QT vận hành hệ thống GDTT HNX/HSX -> Cần bổ sung các nội dung vào Quy trình hoặc bổ sung các Quy trình sau: QT rút tiền: bổ sung nội dung xác thực theo giá trị giao dịch QT mở tài khoản eKYC + đóng tài khoản: bổ sung nội dung xác thực QT quản lý lệnh: bổ sung các nội dung xác thực lệnhCân nhắc bổ sung Quy trình tổng quát về xác thực giao dịch/xác thực thiết bị | I6: Comp, Legal, Mr Duc | J6: KSNB +Legal + CS
A7: 5 | B7: MỤC 1 · 제1절_Yêu cầu chung | C7: ĐIỀU 5 — 제5조 | D7: Ghi nhận thông tin về các yêu cầu giao dịch của khách hàng trên hệ thống; lưu trữ để tra cứu được khi cần thiết (khoản 6 Điều 5). | E7: 고객 거래요청 정보를 시스템에 기록; 필요 시 조회 가능하도록 보관(제5조 제6항). | F7: Có / 예 | G7: OK | H7: Đặt lệnh: đang quản lý qua BOS | I7: Comp, Legal, Mr Duc | J7: Cần tham khảo các công ty khác về cách thực hiện lấy thông tin địa chỉ MAC, Mobile trình duyệt + Web trên MAC OS ko lấy được
A8: 6 | B8: MỤC 1 · 제1절_Yêu cầu chung | C8: ĐIỀU 5 — 제5조 | D8: Thông báo kết quả thực hiện lệnh cho khách hàng ngay sau khi khớp, không vượt quá 10 giây kể từ thời điểm lệnh được khớp (khoản 7 Điều 5). | E8: 체결 즉시 고객에게 결과 통지; 체결 시점부터 10초 초과 금지(제5조 제7항). | F8: Có / 예 | G8: OK | H8: Hiện tại đã có thông báo đẩy/ notification trên toàn bộ các kênh giao dịch: NHSV Pro, WTS/HTS | I8: Comp, Legal, Mr Duc | J8: Trong trường hợp quá 10s chưa có phương án bổ sung, trên thực tế khó xảy ra
A9: 7 | B9: MỤC 1 · 제1절_Yêu cầu chung | C9: ĐIỀU 5 — 제5조 (tiếp) | D9: Khi cung cấp dịch vụ, công ty chứng khoán phải trực tiếp thực hiện: a) Xác thực giao dịch mở tài khoản chứng khoán; b) Xác thực giao dịch đặt lệnh mua bán chứng khoán (điểm a, b khoản 8 Điều 5). | E9: 서비스 제공 시 증권회사가 직접 수행: a) 증권계좌 개설 거래 인증; b) 증권 매매주문 거래 인증(제5조 제8항 a·b호). | F9: Không / 아니오 | G9: Cần hành động | H9: Mở TKCK: xác thực hình thức OCR cho CCCD & khuôn mặt Xác thực giao dịch đặt lệnh CK -> Việc xác thực giao dịch phải được thực hiện ít nhất 1 lần đối với giao dịch đầu tiên của mỗi phiên đăng nhập của khách hàng | I9: Comp, Legal, Mr Duc | J9: Thêm 1 bước smart OTP trước khi đặt lệnh, tham khảo SSI
A10: 8 | B10: MỤC 1 · 제1절_Yêu cầu chung | C10: ĐIỀU 5 — 제5조 (tiếp) | D10: Khi cung cấp dịch vụ, công ty chứng khoán phải trực tiếp thực hiện: Kiểm soát tính hợp lệ của lệnh đặt và chuyển lệnh vào hệ thống giao dịch chứng khoán của Sở GDCK Việt Nam và công ty con (điểm c khoản 8 Điều 5). | E10: c) 주문의 유효성을 통제하고 베트남거래소(VNX) 및 자회사의 증권거래 시스템으로 주문 전송(제5조 제8항 c호). | F10: Có / 예 | G10: OK | I10: Comp, Legal, Mr Duc
A11: 9 | B11: MỤC 1 · 제1절_Yêu cầu chung | C11: ĐIỀU 5 — 제5조 (tiếp) | D11: Áp dụng hình thức xác thực giao dịch điện tử theo một trong 6 hình thức tại Điều 7: OTP (Điều 8), khớp đúng thông tin sinh trắc học (Điều 9), khớp đúng thông tin sinh trắc học thiết bị (Điều 10), FIDO (Điều 11), xác thực hai kênh, chữ ký số. | E11: 제7조의 6가지 인증방식 적용: OTP(제8조), 생체정보 일치(제9조), 기기 저장 생체 일치(제10조), FIDO(제11조), 이중채널 인증, 전자서명. | F11: Có / 예 | G11: OK | H11: Hiện tại các kênh giao dịch đều cần verify qua OTP/ Smart OTP để đăng nhập thành công rồi cho phép đặt lệnh | I11: Comp, Legal, Mr Duc
A12: 10 | B12: MỤC 1 · 제1절_Yêu cầu chung | C12: ĐIỀU 5 — 제5조 (tiếp) | D12: Rà soát, lập kế hoạch, hoàn thiện hệ thống & dữ liệu của khách hàng bảo đảm tuân thủ quy định trong thời hạn 01 năm kể từ ngày Thông tư có hiệu lực thi hành (Điều 31). | E12: 규정 준수를 위해 시스템 및 고객 데이터를 점검·계획·정비; 시행일로부터 1년 이내 완료(제31조). | F12: Chưa đánh giá / 미평가 | G12: Cần hành động | H12: Điều khoản chuyển tiếp — Điều 31. -> Thực hiện sau khi có hiệu lực | I12: Comp, Legal, Mr Duc
A13: 11 | B13: MỤC 1 · 제1절_Yêu cầu chung | C13: ĐIỀU 7–9 — 제7~9조 | D13: Đáp ứng các yêu cầu về xác thực bằng mã khóa dùng 1 lần OTP (Điều 8) Về SMS OTP, Voice OTP, Email OTP, Thẻ ma trận OTP, Soft OTP và Token OTP | E13: OTP 유효시간 준수: SMS 5분, Voice 3분, Email 5분, 매트릭스 카드 2분, Soft OTP 2분, Token OTP 2분(제8조). | F13: Không / 아니오 | G13: Cần hành động | H13: Chi tiết điều 8 1. SMS OTP phải đáp ứng các yêu cầu sau: a) OTP gửi tới khách hàng phải kèm thông tin thông báo để khách hàng nhận biết được mục đích của OTP; b) OTP có hiệu lực tối đa 05 phút kể từ thời điểm được hệ thống tạo. -> Rà soát lại toàn bộ các SMS OTP về thông tin gửi (hiện tại gửi đang không gửi kèm mục đích sử dụng), Rà soát lại thời gian hiệu lực của SMS OTP 2. Voice OTP phải đáp ứng các yêu cầu sau: a) OTP gửi tới khách hàng phải kèm thông tin thông báo để khách hàng nhận biết được mục đích của OTP; b) OTP có hiệu lực tối đa 03 phút kể từ thời điểm cuộc gọi được hệ thống thiết lập thành công. -> NHSV hiện không áp dụng hình thức này 3. Email OTP phải đáp ứng các yêu cầu sau: a) OTP gửi tới khách hàng phải kèm thông tin thông báo để khách hàng nhận biết được mục đích của OTP; b) OTP có hiệu lực tối đa 05 phút kể từ thời điểm được hệ thống tạo. -> NHSV hiện không áp dụng hình thức này 4. Thẻ ma trận OTP phải đáp ứng các yêu cầu sau: a) Thẻ ma trận OTP có thời hạn sử dụng tối đa 01 năm kể từ ngày đăng ký thẻ; b) Yêu cầu xác thực OTP có hiệu lực tối đa 02 phút kể từ thời điểm được hệ thống tạo. -> Thẻ ma trận OTP của NHSV hiện không đáp ứng về thời hạn sử dụng. Phải sửa đổi thời gian về tối đa 1 năm từ ngày đăng kí thẻ. Nghiên cứu triển khai cùng CS Rà soát về hiệu lực 2P để nhập OTP. Hiện không chặn 5. Soft OTP phải đáp ứng các yêu cầu sau: a) Trường hợp phần mềm Soft OTP độc lập với phần mềm ứng dụng Mobile App, phải được tổ chức cung cấp dịch vụ đăng ký, quản lý phần mềm tại kho ứng dụng chính thức của hãng cung cấp hệ điều hành cho thiết bị di động và hướng dẫn cài đặt trên trang thông tin điện tử của tổ chức cung cấp dịch vụ; b) Phần mềm phải có chức năng xác thực khách hàng khi sử dụng lần đầu hoặc khi sử dụng trên thiết bị khác với thiết bị sử dụng lần gần nhất. Việc xác thực khách hàng phải bảo đảm khớp đúng SMS OTP hoặc Voice OTP thông qua số điện thoại di động đã được khách hàng đăng ký với tổ chức cung cấp dịch vụ và khớp đúng thông tin sinh trắc học của khách hàng theo một trong các loại thông tin sinh trắc học quy định tại khoản 12 Điều 3 Thông tư này; c) Phần mềm Soft OTP phải yêu cầu kích hoạt trước khi sử dụng. Mã kích hoạt sử dụng Soft OTP do tổ chức cung cấp dịch vụ cung cấp cho khách hàng và chỉ được sử dụng để kích hoạt trên một thiết bị di động. Mã kích hoạt phải được thiết lập thời hạn hiệu lực sử dụng; d) Phần mềm Soft OTP phải có chức năng kiểm soát truy cập. Trường hợp truy cập sai liên tiếp quá số lần do tổ chức cung cấp dịch vụ quy định (nhưng không quá 10 lần), phần mềm Soft OTP phải tự động khóa không cho khách hàng sử dụng tiếp. Tổ chức cung cấp dịch vụ chỉ mở khóa phần mềm Soft OTP khi khách hàng yêu cầu và phải kiểm tra, nhận biết khách hàng trước khi thực hiện mở khóa, bảo đảm chống gian lận, giả mạo; đ) Mã OTP có hiệu lực tối đa 02 phút kể từ thời điểm được hệ thống tạo. -> Soft OTP của NHSV hiện đã đáp ứng về thời gian hiệu lực không quá 2P. Cần rà soát Khi KH kích hoạt Smart OTP lần đầu, theo quy định phải phải yêu cầu khớp đúg SMS OTP qua số điện thoại đã đăng kí và khớp đúng thông tin sinh trắng học của KH theo ảnh khuôn mặt/vân tay/mống mắt/ADN/giọng nói. NHSV đã yêu cầu KH phải kích hoạt Smart OTP trước khi sử dụng nhưng mã kích hoạt chỉ được sử dụng trên 1 thiết bị và hiệu lực sử dụng cần rà soát lại Phần mềm Soft OTP phải có chức năng kiểm soát truy cập. Rà soát trường hợp truy cập sai liên tiếp quá số lần do tổ chức cung cấp dịch vụ quy định (nhưng không quá 10 lần), phần mềm Soft OTP phải tự động khóa không cho khách hàng sử dụng tiếp. Tổ chức cung cấp dịch vụ chỉ mở khóa phần mềm Soft OTP khi khách hàng yêu cầu và phải kiểm tra, nhận biết khách hàng trước khi thực hiện mở khóa, bảo đảm chống gian lận, giả mạo; 6. Token OTP: OTP có hiệu lực tối đa 02 phút kể từ thời điểm được hệ thống tạo. -> Token OTP NHSV hiện tại không áp dụng | I13: Comp, Legal, Mr Duc
A14: 12 | B14: MỤC 1 · 제1절_Yêu cầu chung | C14: ĐIỀU 7–9 — 제7~9조 | D14: Sinh trắc học khuôn mặt đạt chuẩn FIDO Biometric Requirement: FRR < 5%, FAR < 0,01% (tập mẫu ≥ 10.000); có phát hiện tấn công giả mạo vật thể sống (PAD) (khoản 1 Điều 9). | E14: 얼굴 생체인증 FIDO Biometric Requirement 충족: FRR<5%, FAR<0.01%(표본 1만 이상); 생체 위조공격탐지(PAD) 보유(제9조 제1항). | F14: Chưa đánh giá / 미평가 | G14: Cần check lại | H14: Trường hợp sử dụng các hình thức khớp đúng thông tin sinh trắc học khác cần đảm bảo khả năng phát hiện, ngăn chặn hành vi gian lận, giả mạo tương đương -> IT cần check lại xem hình thức sinh trắc học qua Ekyc của NHSV đã đáp ứng hay chưa và chuẩn bị áp dụng sinh trắc học khi rút tiền phù hợp | I14: Comp, Legal, Mr Duc | J14: Nghiên cứu trao đổi với VNPT về đối chiếu thông tin Face ID có kết nối với Bộ Công An hay không, đã bao gồm trong gói ID Check NHSV đang chuẩn bị đưa vào sử dụng không
A15: 13 | B15: MỤC 1 · 제1절_Yêu cầu chung | C15: ĐIỀU 7–9 — 제7~9조 | D15: Giải pháp PAD do tổ chức tự triển khai hoặc dùng của bên thứ ba phải được chứng nhận bởi Liên minh FIDO hoặc tổ chức quốc tế có tiêu chuẩn tương đương/cao hơn (khoản 3 Điều 9). (K4) Khóa chức năng khi sai quá số lần quy định (≤10 lần), chỉ mở khi KH yêu cầu & nhận biết KH. (K5) Thời gian khớp đúng thông tin sinh trắc học kể từ thời điểm hệ thống ghi nhận yêu cầu xác thực của KH là tối đa 03 phút. (K6): Đối chiếu khớp đúng thông tin STH của KH với 1 trong các dữ liệu: a) Dữ liệu sinh trắc học được lưu trong bộ phận lưu trữ thông tin được mã hóa của thẻ CCCD hoặc thẻ CC đã được xác thực chính xác là do cơ quan Công an cấp hoặc thông qua xác thực tài khoản định danh điện tử của người đó do Hệ thống định danh và xác thực điện tử tạo lập; b) Dữ liệu sinh trắc học đã được thu thập và kiểm tra; bảo đảm sự khớp đúng giữa dữ liệu sinh trắc học của người đó với dữ liệu sinh trắc học trong bộ phận lưu trữ thông tin được mã hóa của thẻ CCCD hoặc thẻ CC đã được xác thực chính xác là do cơ quan Công an cấp, hoặc với dữ liệu sinh trắc học của người đó thông qua xác thực tài khoản định danh điện tử do Hệ thống định danh và xác thực điện tử tạo lập; c) Dữ liệu sinh trắc học của người đó được lưu trong Cơ sở dữ liệu quốc gia về dân cư trong trường hợp sử dụng thẻ CCCD không có bộ phận lưu trữ thông tin được mã hóa. | E15: PAD 솔루션은 자체 구축 또는 제3자 사용 시 FIDO Alliance 또는 동등·상위 기준 국제기관의 인증 필요(제9조 제3항). | F15: Chưa đánh giá / 미평가 | G15: Cần check lại | H15: Check xem đối tác đã đáp ứng chứng nhận bới liên minh FIDO và giải pháp NHSV sắp áp dụng đã đáp ứng các yêu cầu hay chưa | I15: Comp, Legal, Mr Duc
A16: 14 | B16: MỤC 1 · 제1절_Yêu cầu chung | C16: ĐIỀU 7–9 — 제7~9조 | D16: Xác thực khớp đúng thông tin sinh trắc học thiết bị phải đáp ứng các yêu cầu sau: 1. Chỉ cho phép kích hoạt sử dụng sau khi có sự đồng ý của khách hàng và khách hàng đã thực hiện ít nhất một giao dịch thành công bằng hình thức xác thực khác. 2. Thời gian thực hiện khớp đúng thông tin sinh trắc học tối đa 02 phút kể từ thời điểm thiết bị bắt đầu thực hiện việc xác thực. | E16: 기기 생체 정보 일치 인증 시 다음 요구 사항을 충족할 것: 고객의 동의 및 다른 인증 수단을 통한 최소 1회 이상의 성공적인 거래 실적이 있는 경우에 한하여 활성화 및 사용을 허용함. 생체 정보 일치 확인 시간은 기기가 인증을 개시한 시점부터 최대 2분 이내로 제한함. | F16: N/A / 해당없음 | G16: OK | H16: NHSV Pro yêu cầu khách hàng phải đăng nhập bằng Password & Xác thực OTP trước khi cho phép kích hoạt phương thức đăng nhập bằng biometric -> IT đang áp dụng hình thức đặt lệnh xác thực qua Smart OTP, IT dự kiến không áp dụng sinh trắc học thiết bị. Nếu sau này áp dụng đặt lệnh qua sinh trắc học thiết bị thì cần phải tuân thủ | I16: Comp, Legal, Mr Duc
A17: 15 | B17: MỤC 1 · 제1절_Yêu cầu chung | C17: ĐIỀU 7–9 — 제7~9조 | D17: Xác thực FIDO phải đáp ứng các yêu cầu sau: 1. Khóa bí mật được lưu giữ an toàn trên thiết bị của khách hàng. Khách hàng sử dụng hình thức xác thực bằng mã PIN hoặc khớp đúng thông tin sinh trắc học thiết bị để truy cập, sử dụng khóa bí mật khi thực hiện giao dịch. 2. Khóa công khai được lưu trữ an toàn tại tổ chức cung cấp dịch vụ và được liên kết với tài khoản giao dịch trực tuyến của khách hàng. 3. Giải pháp do tổ chức cung cấp dịch vụ tự triển khai hoặc sử dụng của bên thứ ba cung cấp phải được cấp chứng nhận của tổ chức được Liên minh FIDO (FIDO Alliance) công nhận. | E17: FIDO 인증 시 다음 요구 사항을 충족할 것: 개인키(Private Key)는 고객 기기에 안전하게 보관되어야 함. 고객은 거래 수행 시 개인키에 접근 및 이를 사용하기 위해 PIN 번호 인증 또는 기기 생체 정보 일치 인증 수단을 사용함. 공개키(Public Key)는 서비스 제공기관에 안전하게 저장되고, 고객의 전자금융거래 계좌와 연계되어야 함. 서비스 제공기관이 자체 구축하거나 제3자가 제공하는 솔루션은 FIDO 얼라이언스(FIDO Alliance)가 공인한 기관으로부터 인증을 획득한 것일 것. | F17: N/A / 해당없음 | G17: OK | I17: Comp, Legal, Mr Duc
A18: 16 | B18: MỤC 1 · 제1절_Yêu cầu chung | C18: ĐIỀU 12–13 — 제12~13조 | D18: Mở/đóng tài khoản GDCK & tài khoản lưu ký chứng khoán: xác thực khớp đúng sinh trắc học (Điều 9) với cá nhân & người đại diện hợp pháp của tổ chức; hợp đồng xác nhận bằng chữ ký số (khoản 1 Điều 12). | E18: 증권계좌·예탁계좌 개설/해지: 개인 및 법인 대표자에 대해 생체정보 일치 인증(제9조); 계약은 전자서명으로 확인(제12조 제1항). | F18: Không / 아니오 | G18: Cần hành động | H18: Quy trình mở TKCK có yêu cầu xác thực sinh trắc học (Liveness detect & xác thực chân dung chủ giấy tờ) -> Hiện tại khách hàng đang có thể đóng tài khoản tại quầy hoặc gửi hồ sơ về quầy và CS gọi điện xác nhận với KH. Đóng tài khoản như vậy cũng là chưa xác thực bằng sinh trắc học. Nếu cho KH tổ chức mở tài khoản ekyc cũng cần sinh trắc học khuôn mặt và cân nhắc mở tính năng đóng tài khoản online | I18: Comp, Legal, Mr Duc | J18: Nếu cho KH tổ chức mở tài khoản ekyc cũng cần sinh trắc học khuôn mặt và cân nhắc mở tính năng đóng tài khoản online
A19: 17 | B19: MỤC 1 · 제1절_Yêu cầu chung | C19: ĐIỀU 12–13 — 제12~13조 | D19: Giao dịch chứng khoán trực tuyến: áp dụng xác thực khớp đúng sinh trắc học (Điều 9); xác thực ít nhất với giao dịch đầu tiên mỗi phiên đăng nhập; xác thực & giao dịch trên cùng một thiết bị (khoản 2 Điều 12). | E19: 온라인 증권거래: 생체정보 일치 인증(제9조) 적용; 로그인 세션별 최초 거래 인증; 인증과 거래는 동일 기기에서 수행(제12조 제2항). | F19: Không / 아니오 | G19: Cần hành động | I19: Comp, Legal, Mr Duc | J19: Cần phải xây dựng tính năng quản lý thiết bị
A20: 18 | B20: MỤC 1 · 제1절_Yêu cầu chung | C20: ĐIỀU 12–13 — 제12~13조 | D20: Đặt lệnh qua điện thoại: KH dùng số điện thoại đã đăng ký + tối thiểu số định danh cá nhân & thông tin xác thực yếu tố bí mật; chỉ thực hiện khi thông tin trùng khớp dữ liệu đã lưu (khoản 3 Điều 12). | E20: 전화 주문: 등록된 전화번호 + 최소 개인식별번호 및 비밀요소 인증정보 사용; 등록·보관된 정보와 일치할 때만 거래 수행(제12조 제3항). | F20: Có / 예 | G20: Cần hành động | H20: Khoản 3 Điều 12: đặt lệnh qua điện thoại — giao dịch chỉ được thực hiện khi thông tin KH cung cấp trùng khớp với thông tin đã đăng ký và lưu trong hệ thống GDTT. Tính đến hiện tại mình có đáp ứng, tuy nhiên CS đã gửi yêu cầu cho BA về việc đồng bộ được SĐT đăng ký của KH + thông tin khách hàng được hiển thị (khi KH dùng đúng SĐT đăng ký liên hệ đến NHSV) | I20: Comp, Legal, Mr Duc
A21: 19 | B21: MỤC 1 · 제1절_Yêu cầu chung | C21: ĐIỀU 12–13 — 제12~13조 | D21: Rút/chuyển tiền khỏi tài khoản GDCK: < 10 triệu VND áp dụng tối thiểu 1 hình thức tại Điều 7; ≥ 10 triệu VND áp dụng tối thiểu hình thức Xác thực khớp đúng thông tin sinh trắc học. | E21: 증권계좌 출금·이체: 1천만 VND 미만 제7조 1가지 이상; 1천만 VND 이상 제9조 (생체인식) 인증 적용(제12조 제4항). | F21: Không / 아니오 | G21: Cần hành động | H21: Khoản 5 Điều 12: với giao dịch không thuộc các khoản trên (1-4) điều 12, tổ chức phân loại & đánh giá mức độ rủi ro để thỏa thuận với KH hình thức xác thực phù hợp, áp dụng theo một trong các hình thức tại Điều 7. -> Dưới 10tr rút tiền chưa có yêu cầu OTP và trên 10tr chưa sinh trắc học | I21: Comp, Legal, Mr Duc
A22: 20 | B22: MỤC 1 · 제1절_Yêu cầu chung | C22: ĐIỀU 12–13 — 제12~13조 | D22: Nhà đầu tư nước ngoài cư trú tại Việt Nam: mở, sử dụng, đóng tài khoản GDCK & lưu ký theo Điều 12 (khoản 1 Điều 13). | E22: 베트남 거주 외국인 투자자: 제12조에 따라 증권·예탁계좌 개설·이용·해지(제13조 제1항). | F22: Chưa đánh giá / 미평가 | G22: Cần check lại | H22: Tương tự NĐT trong nước -> Ms Ngân cung cấp thông tin việc Hiện tại mình đang không cung cấp DV cho khách hàng NN không cư trú (Tuy nhiên trong quá trình MTK mình đã có danh sách AML để xử lý trên BOS) nhưng đây là điều khoản về NĐT nước ngoài cư trú tại VN | I22: Comp, Legal, Mr Duc
A23: 21 | B23: MỤC 1 · 제1절_Yêu cầu chung | C23: ĐIỀU 12–13 — 제12~13조 | D23: Nhà đầu tư nước ngoài không cư trú: ủy quyền cho tổ chức KDCK nước ngoài/tổ chức có HĐ dịch vụ. Phải nhận biết KH & tổ chức được ủy quyền theo pháp luật phòng, chống rửa tiền (khoản 2, 3, 4 Điều 13). | E23: 비거주 외국인 투자자: 외국 증권사/서비스 계약 기관에 위임; 서비스 제공기관은 자금세탁방지법에 따라 고객 및 수임기관 확인(제13조 제2·3·4항). | F23: Chưa đánh giá / 미평가 | G23: Cần check lại | H23: Điều 13: (K3) Không áp dụng điểm a,b K8 Đ5; Đ9; điểm b K1 Đ12; K4 Đ12 — dùng xác nhận điện tử thể hiện sự chấp thuận, kiểm tra hợp pháp/hợp lệ & nhận biết KH theo PCRT. (K4) Nhận lệnh qua hệ thống truyền lệnh trung gian: kênh truyền riêng, giao thức FIX hoặc tương đương, có quy trình tiếp nhận-kiểm tra-xử lý lệnh. -> Phòng ban phụ trách chưa có đánh giá | I23: Comp, Legal, Mr Duc
A24: 22 | B24: MỤC 2 · 제2절 | C24: ĐIỀU 14 — 제14조 | D24: Tuân thủ pháp luật về chứng khoán & an ninh mạng khi triển khai API; dừng triển khai dịch vụ khi phát hiện API có nguy cơ gây rủi ro cho thị trường (khoản 1 Điều 14). | E24: API 도입 시 증권법 및 사이버보안 법규 준수; API가 시장 위험을 초래할 우려 발견 시 도입 중단(제14조 제1항). | F24: Không / 아니오 | G24: Cần hành động | H24: Cần check tuân thủ các yêu cầu của pháp luật về API và tuân thủ toàn bộ | I24: Comp, Legal, Mr Hoang, Mr Duc
A25: 23 | B25: MỤC 2 · 제2절 | C25: ĐIỀU 14 — 제14조 | D25: Tuân thủ pháp luật về giữ bí mật, cung cấp thông tin KH & bảo vệ dữ liệu cá nhân; xử lý dữ liệu cá nhân chỉ phục vụ chính KH đó, trừ trường hợp pháp luật có quy định khác (khoản 2 Điều 14). | E25: 비밀유지·고객정보 제공·개인정보보호 법규 준수; 개인정보 처리는 해당 고객 목적에 한정(법령에 다른 규정이 있는 경우 제외)(제14조 제2항). | F25: Chưa đánh giá / 미평가 | G25: Cần check lại | H25: Cần check lại điều khoản trong HD với đối tác xem đã có điều khoản liên quan đến bảo vệ dữ liệu cá nhân chưa? (Tham chiếu luật bảo vệ dữ liệu cá nhân) | I25: Comp, Legal, Mr Hoang, Mr Duc
A26: 24 | B26: MỤC 2 · 제2절 | C26: ĐIỀU 14 — 제14조 | D26: Dữ liệu xử lý phải được quản lý, lưu trữ, khai thác, sử dụng đúng mục đích tại hợp đồng & phù hợp pháp luật; bảo đảm cập nhật, chính xác; trường hợp sai lệch phải đính chính, hiệu chỉnh kịp thời theo thỏa thuận các bên (khoản 3, 4 Điều 14). | E26: 처리 데이터는 계약상 목적·법령에 부합하게 관리·보관·활용; 최신성·정확성 보장; 오류 시 당사자 합의에 따라 즉시 정정·보정(제14조 제3·4항). | F26: Chưa đánh giá / 미평가 | G26: Cần check lại | H26: Check lại điều khoản hd với đối tác. | I26: Comp, Legal, Mr Hoang, Mr Duc
A27: 25 | B27: MỤC 2 · 제2절 | C27: ĐIỀU 14 — 제14조 | D27: Có hợp đồng triển khai API với bên thứ ba (khoản 5 Điều 14). | E27: 제3자와 API 도입 계약 체결(제14조 제5항). | F27: Chưa đánh giá / 미평가 | G27: Cần check lại | H27: Nội dung HĐ (khoản 5): a) Cam kết an toàn-bảo mật & bảo vệ dữ liệu KH; b) Cam kết dùng dữ liệu đúng phạm vi-mục đích & chịu trách nhiệm khi rò rỉ/sai lệch/sai mục đích; c) Thông tin dịch vụ qua API; d) Phí dịch vụ (nếu có); đ) Cấp độ ANM hệ thống bên thứ ba; e) Quyền truy cập dữ liệu các bên; g) Thông báo khi nhân sự vi phạm; h) Trách nhiệm bồi thường & cung cấp thông tin; i) Điều khoản chấm dứt HĐ. -> Hiện tại NHSV có đang cung cấp API cho đối tác Stag? Đã có hợp đồng hay chưa và HĐ này cần được review lại để đảm bảo các nội dung theo yêu cầu của thông tư | I27: Comp, Legal, Mr Hoang, Mr Duc
A28: 26 | B28: MỤC 2 · 제2절 | C28: ĐIỀU 14 — 제14조 | D28: Lập & lưu giữ hồ sơ kỹ thuật và hồ sơ phối hợp triển khai API tại hai bên (khoản 6 Điều 14). | E28: API 기술문서 및 협력 도입 문서를 양측에서 작성·보관(제14조 제6항). | F28: Chưa đánh giá / 미평가 | G28: Cần check lại | H28: Hồ sơ (khoản 6): a) Mô hình triển khai từng bên (sơ đồ luồng dữ liệu, phân vùng bảo mật, điểm kết nối API); b) Thông số kỹ thuật chi tiết (giao thức, điểm cuối, phiên bản, luồng dữ liệu, phương thức xác thực); c) Cơ chế xác thực & phân quyền người dùng; d) Cơ chế quản lý-kiểm soát-giới hạn tần suất truy cập; đ) Hồ sơ biện pháp bảo vệ ANM; e) Tài liệu khác liên quan (nếu có). -> Đã có hồ sơ này với đối tác đang kết nối API (Stag) hay chưa? Hồ sơ có đầy đủ thông tin theo yêu cầu thông tư không? Lưu trữ ở đâu | I28: Comp, Legal, Mr Hoang, Mr Duc
A29: 27 | B29: MỤC 2 · 제2절 | C29: ĐIỀU 15 — 제15조 | D29: Hoàn thiện cơ sở hạ tầng hệ thống thông tin phục vụ triển khai API; xây dựng và ban hành các tài liệu hướng dẫn kết nối, xử lý dữ liệu (khoản 1, 2 Điều 15). | E29: API 도입을 위한 정보시스템 인프라 완비; 연동·데이터 처리 안내 문서 수립·발행(제15조 제1·2항). | F29: Không / 아니오 | G29: Cần hành động | H29: Tài liệu hướng dẫn kết nối và xử lý dữ liệu chưa ban hành | I29: Comp, Legal, Mr Hoang, Mr Duc
A30: 28 | B30: MỤC 2 · 제2절 | C30: ĐIỀU 15 — 제15조 | D30: Bảo đảm chất lượng dữ liệu; thông báo kịp thời cho bên thứ ba khi sai lệch & phối hợp đính chính. Bảo đảm an ninh mạng cho hệ thống API tối thiểu bằng cấp độ hệ thống GDTT (khoản 3, 4 Điều 15). | E30: 데이터 품질 보장; 오류 시 제3자에 즉시 통지·정정 협력. API 시스템 사이버보안을 온라인거래 시스템 등급 이상으로 보장(제15조 제3·4항). | F30: Có / 예 | G30: OK | H30: Đã pentest API thành công khi test Level 3 ATTT | I30: Comp, Legal, Mr Hoang, Mr Duc
A31: 29 | B31: MỤC 2 · 제2절 | C31: ĐIỀU 15 — 제15조 | D31: Cung cấp công cụ/chức năng cho phép KH: a) Tra cứu các dữ liệu KH đồng ý cho bên thứ 3 xử lý; b) Rút lại sự đồng ý theo quy định pháp luật (khoản 5 Điều 15). | E31: 고객에게 다음 도구·기능 제공: a) 고객이 처리에 동의한 데이터 조회; b) 법령에 따른 동의 철회(제15조 제5항). | F31: Không / 아니오 | G31: Cần hành động | H31: Cân nhắc thêm phương án xử lý | I31: Comp, Legal, Mr Hoang, Mr Duc
... A45: 43 | B45: MỤC 3 · 제3절 | C45: ĐIỀU 18 — 제18조 | D45: Phần mềm ứng dụng trực tuyến: mã hóa điểm-đầu-đến-điểm-cuối dữ liệu truyền; bảo đảm tính toàn vẹn dữ liệu giao dịch (Điều 18). | E45: 온라인 응용 소프트웨어: 전송 데이터 종단간 암호화; 거래 데이터 무결성 보장(제18조). | F45: Có / 예 | G45: OK | H45: Dùng giao thức HTTPS và chứng thư số SSL (App NHSV đảm bảo cơ chế này, có mua certificate của đối tác thứ 3, có mã hóa) | I45: Mr Van Main, Mr Choi
A46: 44 | B46: MỤC 3 · 제3절 | C46: ĐIỀU 18 — 제18조 | D46: Phần mềm ứng dụng trực tuyến: kiểm soát phiên đăng nhập (tự ngắt khi không thao tác); chống đăng nhập tự động; phòng ngừa rò rỉ dữ liệu (DLP) (Điều 18). | E46: 온라인 응용 소프트웨어: 로그인 세션 통제(미조작 시 자동 종료); 자동 로그인 방지; 데이터 유출 방지(DLP)(제18조). | F46: Không / 아니오 | G46: Cần hành động | H46: NHSV đã mua giải pháp DLP nhưng chỉ đáp ứng được check dữ liệu của người dùng là nhân viên công ty chứ chưa áp dụng, tích hợp đc với các ứng dụng online app web API | I46: Mr Van Main, Mr Choi | J46: https://webtrading.nhsv.vn/v4/auth/login
A47: 45 | B47: MỤC 3 · 제3절 | C47: ĐIỀU 18 — 제18조 | D47: Phần mềm ứng dụng trực tuyến: lưu thông tin định danh thiết bị di động/máy tính; lưu nhật ký giao dịch chứng khoán & nhật ký rút/chuyển tiền với đầy đủ trường thông tin theo quy định (Điều 18). | E47: 온라인 응용 소프트웨어: 모바일/PC 기기 식별정보 저장; 규정 항목을 갖춘 증권거래 로그 및 출금·이체 로그 보관(제18조). | F47: Không / 아니오 | G47: Cần hành động | H47: Nhật ký GD rút/chuyển tiền ra khỏi TKCK: Chưa lưu thông tin định danh thiết bị || 4. Nhật ký giao dịch chứng khoán gồm các thông tin sau: tên khách hàng, loại hình khách hàng, số tài khoản, thời gian nhận lệnh (ngày, giờ phút), mã chứng khoán, phương thức giao dịch, loại lệnh, số lượng và giá giao dịch, hình thức xác thực giao dịch, thời gian xác thực giao dịch, thông tin định danh thiết bị, địa chỉ IP mạng. 5. Nhật ký giao dịch rút, chuyển tiền ra khỏi tài khoản giao dịch chứng khoán gồm các thông tin sau: tên khách hàng, số tài khoản, số tiền, tài khoản ngân hàng nhận tiền, thời gian giao dịch, hình thức xác thực giao dịch, thông tin định danh thiết bị, địa chỉ IP mạng. Mobile App cũng phải tuân thủ các quy định điều 1-3 tại điều 18 về quản lý phiên bản, các tính ngăng bắt buộc, có đủ các chức năng lưu trữ thông tin 1#Nhật ký GD chứng khoán: Đối với KH giao dịch qua WTS trên điện thoại hoặc thiết bị dùng hệ điều hành MacOS và mở WTS trên trình duyệt khác SAFARI: Đang chưa lấy được thông tin định danh thiết bị. 2#Nhật ký GD rút/chuyển tiền ra khỏi TKCK: Chưa lưu thông tin định danh thiết bị | I47: Mr Van Main, Mr Choi
A48: 46 | B48: MỤC 3 · 제3절 | C48: ĐIỀU 18 — 제18조 | D48: Mobile App: đăng ký kho ứng dụng chính thức; cài trên thiết bị sử dụng SĐT KH đã đăng ký; giải pháp phòng, chống, phát hiện hành vi can thiệp trái phép vào ứng dụng GDTT trên thiết bị di động của KH; không cho phép lưu mã PIN/mã khóa bí mật; xác thực khi đăng nhập lần đầu hoặc đăng nhập trên thiết bị mới (Điều 18). | E48: 모바일앱: 공식 앱스토어 등록; 등록 번호 기기 설치; 기기 내 거래앱 무단 변조 방지·탐지 솔루션; PIN 미저장; 새 기기 로그인 시 인증(제18조). | F48: Không / 아니오 | G48: Cần hành động | H48: NHSV chưa có giải pháp để xác minh đc là SDT đã cài đặt trên đúng thiết bị mà NHSV đã lưu thông tin đăng kí, khi đăng nhập trên thiết bị mới cũng chưa có (VD bắt buộc App phải lưu được thông tin IMEI khi KH đăng nhập lần đầu và khi có thay đổi phải yêu cầu KH xác thực lại thay thiết bị). NHSV chưa có giải pháp để phòng, chống, phát hiện hành vi can thiệp trái phép vào ứng dụng GDTT trên thiết bị di động của KH | I48: Mr Van Main, Mr Choi
A49: 47 | B49: MỤC 3 · 제3절 | C49: ĐIỀU 18 — 제18조 | D49: Hệ quản trị CSDL có bản quyền, bảo vệ & phân quyền truy cập, cập nhật bản vá; ghi nhật ký truy cập và thao tác khi truy cập CSDL (Điều 18). | E49: DBMS 정품·보호·접근권한 분리·패치; DB 접근 및 작업 로그 기록(제18조). | F49: Có / 예 | G49: OK | H49: Đang thực hiện theo dự án ATTT Level 3 | I49: Mr Van Main, Mr Choi
A50: 48 | B50: MỤC 3 · 제3절 | C50: ĐIỀU 19 — 제19조 | D50: Mạng: tường lửa phân vùng; không lưu thông tin KH ở phân vùng internet/DMZ; hạn chế dịch vụ/cổng kết nối không sử dụng hoặc không cần thiết (Điều 19). | E50: 네트워크: 구간 방화벽; 인터넷/DMZ 구역에 고객정보 미저장; 불필요 서비스·포트 제한(제19조). | F50: Có / 예 | G50: OK | H50: Đã pass qua các lần kiểm tra của Sở | I50: Mr Van Main, Mr Choi
A51: 49 | B51: MỤC 3 · 제3절 | C51: ĐIỀU 19 — 제19조 | D51: Kết nối từ bên ngoài mạng nội bộ vào hệ thống giao dịch trực tuyến để quản trị chỉ được thực hiện trong trường hợp không thể kết nối từ mạng nội bộ và phải tuân thủ các quy định : được cấp có thẩm quyền phê duyệt; dùng VPN/tương đương; thiết bị kết nối được cài đặt phần mềm bảo đảm an toàn, bảo mật; tối thiểu 02 yếu tố xác thực; giao thức mã hóa (Điều 19). | E51: 원격 관리 접속: 승인 필요; VPN/동등 사용; 연결 기기에 보안 SW 설치; 최소 2요소 인증; 암호화 프로토콜(제19조). | F51: Có / 예 | G51: Cần hành động | H51: Hiện tại việc phê duyệt VPN được thực hiện đơn sơ qua email nhưng chưa có văn bản nào lưu trữ. Chưa có quy định đối chiếu để thực hiện -> Cần ban hành quy trình nội bộ về việc quản lý truy cập vào hệ thống giao dịch trực tuyến | I51: Mr Van Main, Mr Choi
A52: 50 | B52: MỤC 3 · 제3절 | C52: ĐIỀU 19 — 제19조 | D52: Đặt lệnh qua điện thoại: công ty chứng khoán phải trang bị hệ thống tổng đài có ghi âm, quản lý, lưu trữ, tra cứu; đường truyền có dự phòng, sẵn sàng cao, bảo đảm khả năng cung cấp dịch vụ liên tục (Điều 19). | E52: 전화 주문: 녹음·관리·보관·조회 가능한 콜센터; 예비·고가용 회선으로 서비스 연속성 보장(제19조). | F52: Có / 예 | G52: OK | H52: Mọi cuộc gọi phải được ghi âm, lưu trữ đầy đủ. Sau này có thể tham khảo thực hiện call center để nâng cao chức năng quản lý cuộc gọi | I52: Mr Van Main, Mr Choi
A53: 51 | B53: MỤC 3 · 제3절 | C53: ĐIỀU 20–22 — 제20~22조 | D53: Định kỳ sao lưu dự phòng: tập tin cấu hình hệ thống; bản dự phòng hệ điều hành máy chủ, hệ quản trị CSDL; dữ liệu, thông tin liên quan đến giao dịch của khách hàng (khoản 1 Điều 20). | E53: 정기 백업: 시스템 구성 파일; 서버 OS·DBMS 예비본; 고객 거래 관련 데이터·정보(제20조 제1항). | F53: Có / 예 | G53: OK | H53: Việc lưu trữ dữ liệu phải bảo đảm tính an toàn, bảo mật, đầy đủ và toàn vẹn của dữ liệu phục vụ cho công tác kiểm tra, đối chiếu, xác thực khách hàng trong quá trình sử dụng dịch vụ và cung cấp thông tin khi có yêu cầu của cơ quan có thẩm quyền -> Hiện tại NHSV sao lưu hằng ngày | I53: Mr Van Main, Mr Choi
...

Sheet Korean
A1: 번호 | B1: 해당 절 | C1: 처리 대상 항목 — 요건 | D1: 처리 대상 항목 | E1: 참조 조항
A2: 1 | B2: 제1절 (일반규정) | C2: =D2 -> 제공 서비스에 관한 정보를 공시하여 고객이 가입 전 또는 가입 시점에 접근 가능하도록 보장(제5조 제1·2항). | D2: 제공 서비스에 관한 정보를 공시하여 고객이 가입 전 또는 가입 시점에 접근 가능하도록 보장(제5조 제1·2항). | E2: 제5조
A3: 2 | B3: 제1절 (일반규정) | C3: =D3 -> 증권회사는 온라인 증권거래 서비스 제공 전 UBCKNN 승인을 취득; 서류는 NĐ 155/2020 제203조, 양식은 부록 I (제5조 제3항). | D3: 증권회사는 온라인 증권거래 서비스 제공 전 UBCKNN 승인을 취득; 서류는 NĐ 155/2020 제203조, 양식은 부록 I (제5조 제3항). | E3: 제5조
A4: 3 | B4: 제1절 (일반규정) | C4: =D4 -> 서비스 제공은 고객과의 계약 또는 계약 조항으로 표시되어야 함(제5조 제4항). 계약에 다음 정보 포함: • 온라인 거래 방식 및 해당 거래 유형 • 서비스 가입에 등록한 휴대전화 번호. 서비스 제공기관은 해당 번호가 고객의 적법한 사용 권한에 속함을 확인하는 조치 보유 • 각 당사자의 위험 및 배상 책임 | D4: 서비스 제공은 고객과의 계약 또는 계약 조항으로 표시되어야 함(제5조 제4항). 계약에 다음 정보 포함: • 온라인 거래 방식 및 해당 거래 유형 • 서비스 가입에 등록한 휴대전화 번호. 서비스 제공기관은 해당 번호가 고객의 적법한 사용 권한에 속함을 확인하는 조치 보유 • 각 당사자의 위험 및 배상 책임 | E4: 제5조
A5: 4 | B5: 제1절 (일반규정) | C5: =D5 -> 본 시행규칙, 증권법 및 관련 법규에 부합하는 온라인 거래 절차 제정(제5조 제5항). | D5: 본 시행규칙, 증권법 및 관련 법규에 부합하는 온라인 거래 절차 제정(제5조 제5항). | E5: 제5조
A6: 5 | B6: 제1절 (일반규정) | C6: =D6 -> 서비스 제공 시 증권회사가 직접 수행: a) 증권계좌 개설 거래 인증; b) 증권 매매주문 거래 인증(제5조 제8항 a·b호). | D6: 서비스 제공 시 증권회사가 직접 수행: a) 증권계좌 개설 거래 인증; b) 증권 매매주문 거래 인증(제5조 제8항 a·b호). | E6: 제5조 (계속)
A7: 6 | B7: 제1절 (일반규정) | C7: =D7 -> 규정 준수를 위해 시스템 및 고객 데이터를 점검·계획·정비; 시행일로부터 1년 이내 완료(제31조). | D7: 규정 준수를 위해 시스템 및 고객 데이터를 점검·계획·정비; 시행일로부터 1년 이내 완료(제31조). | E7: 제5조 (계속)
A8: 7 | B8: 제1절 (일반규정) | C8: =D8 -> OTP 유효시간 준수: OTP카드 1년, SMS 5분, Voice 3분, Email 5분, 매트릭스 카드 2분, Soft OTP 2분, Token OTP 2분(제8조). | D8: OTP 유효시간 준수: OTP카드 1년, SMS 5분, Voice 3분, Email 5분, 매트릭스 카드 2분, Soft OTP 2분, Token OTP 2분(제8조). | E8: 제7~9조
A9: 8 | B9: 제1절 (일반규정) | C9: =D9 -> 얼굴 생체인증 FIDO Biometric Requirement 충족: FRR<5%, FAR<0.01%(표본 1만 이상); 생체 위조공격탐지(PAD) 보유(제9조 제1항). | D9: 얼굴 생체인증 FIDO Biometric Requirement 충족: FRR<5%, FAR<0.01%(표본 1만 이상); 생체 위조공격탐지(PAD) 보유(제9조 제1항). | E9: 제7~9조
A10: 9 | B10: 제1절 (일반규정) | C10: =D10 -> PAD 솔루션은 자체 구축 또는 제3자 사용 시 FIDO Alliance 또는 동등·상위 기준 국제기관의 인증 필요(제9조). | D10: PAD 솔루션은 자체 구축 또는 제3자 사용 시 FIDO Alliance 또는 동등·상위 기준 국제기관의 인증 필요(제9조). | E10: 제7~9조
A11: 10 | B11: 제1절 (일반규정) | C11: =D11 -> 생체정보 일치에 관한 추가 규정. 규정 횟수(10회 이하) 초과 오류 시 기능 잠금, 고객 요청 및 고객 확인 시에만 해제. 생체정보 일치 확인 시간은 시스템이 고객의 인증 요청을 기록한 시점부터 최대 3분. 고객의 생체정보를 다음 데이터 중 하나와 대조하여 일치 확인: a) 공안기관 발급으로 정확히 인증된 CCCD(시민카드) 또는 CC 카드의 암호화 정보저장부에 저장된 생체정보, 또는 전자식별인증시스템이 생성한 본인의 전자식별계정 인증을 통한 생체정보; b) 수집·검사된 생체정보로서, 본인의 생체정보가 공안기관 발급으로 인증된 CCCD 또는 CC 카드의 암호화 저장부 생체정보와 일치하거나, 전자식별인증시스템이 생성한 본인의 전자식별계정 인증 생체정보와 일치함을 보장; c) 암호화 정보저장부가 없는 CCCD 카드 사용 시, 국가 인구 데이터베이스에 저장된 본인의 생체정보. | D11: 생체정보 일치에 관한 추가 규정. 규정 횟수(10회 이하) 초과 오류 시 기능 잠금, 고객 요청 및 고객 확인 시에만 해제. 생체정보 일치 확인 시간은 시스템이 고객의 인증 요청을 기록한 시점부터 최대 3분. 고객의 생체정보를 다음 데이터 중 하나와 대조하여 일치 확인: a) 공안기관 발급으로 정확히 인증된 CCCD(시민카드) 또는 CC 카드의 암호화 정보저장부에 저장된 생체정보, 또는 전자식별인증시스템이 생성한 본인의 전자식별계정 인증을 통한 생체정보; b) 수집·검사된 생체정보로서, 본인의 생체정보가 공안기관 발급으로 인증된 CCCD 또는 CC 카드의 암호화 저장부 생체정보와 일치하거나, 전자식별인증시스템이 생성한 본인의 전자식별계정 인증 생체정보와 일치함을 보장; c) 암호화 정보저장부가 없는 CCCD 카드 사용 시, 국가 인구 데이터베이스에 저장된 본인의 생체정보. | E11: 제7~9조
A12: 11 | B12: 제1절 (일반규정) | C12: =D12 -> 증권계좌·예탁계좌 개설/해지: 개인 및 법인 대표자에 대해 생체정보 일치 인증(제9조); 계약은 전자서명으로 확인(제12조 제1항). | D12: 증권계좌·예탁계좌 개설/해지: 개인 및 법인 대표자에 대해 생체정보 일치 인증(제9조); 계약은 전자서명으로 확인(제12조 제1항). | E12: 제12~13조
A13: 12 | B13: 제1절 (일반규정) | C13: =D13 -> 온라인 증권거래: 생체정보 일치 인증(제9조) 적용; 로그인 세션별 최초 거래 인증; 인증과 거래는 동일 기기에서 수행(제12조 제2항). | D13: 온라인 증권거래: 생체정보 일치 인증(제9조) 적용; 로그인 세션별 최초 거래 인증; 인증과 거래는 동일 기기에서 수행(제12조 제2항). | E13: 제12~13조
... A46: 45 | B46: 제3절 (인프라) | C46: =D46 -> 온라인 서비스 제공을 위해 도입 중인 API 서비스 목록(있는 경우)을 웹사이트에 공개(제26조 제2항). | D46: 온라인 서비스 제공을 위해 도입 중인 API 서비스 목록(있는 경우)을 웹사이트에 공개(제26조 제2항). | E46: 제26조
